<?xml version="1.0"?>
<robot name="movable_base" xmlns:xacro="http://ros.org/wiki/xacro">

<xacro:include filename="$(find ur_with_cam_gazebo)/urdf/inc/ur_common.xacro" />

<xacro:macro name="retractable_base" params="prefix arm_prefix
    x_move_joint_lower_limit:=-1   x_move_joint_upper_limit:=1
    y_move_joint_lower_limit:=-1   y_move_joint_upper_limit:=1
    theta_joint_lower_limit:={-2*pi}   theta_joint_upper_limit:{2*pi}">


<joint name="world_joint" type="fixed">
  <parent link="world" />
  <child link = "${prefix}move_base_link" />
  <origin xyz="0.0 0.0 0.0" rpy="0.0 0.0 0.0" />
</joint>

<link name="${prefix}move_base_link" >
  <!--xacro:cylinder_inertial radius="0.06" length="0.2" mass="1">
    <origin xyz="0.0 0.0 0.0" rpy="0 0 0" />
  </xacro:cylinder_inertial-->
</link>

<joint name="${prefix}x_move_joint" type="prismatic">
    <parent link="${prefix}base_link" />
    <child link = "${prefix}move_x_link" />
    <origin xyz="0.0 0.0 0.6" rpy="0.0 0.0 0.0" />
    <axis xyz="1 0 0" />
    <limit lower="-1" upper="1" effort="1000.0" velocity="3.15"/>
    <dynamics damping="0.0" friction="0.0"/>
</joint>

<link name="${prefix}move_x_link" >
    <xacro:cylinder_inertial radius="0.06" length="0.2" mass="1">
      <origin xyz="0.0 0.0 0.0" rpy="0 0 0" />
    </xacro:cylinder_inertial>
</link>

<joint name="${prefix}y_move_joint" type="prismatic">
    <parent link="${prefix}move_x_link" />
    <child link = "${prefix}move_y_link" />
    <origin xyz="0.0 0.0 0.0" rpy="0.0 0.0 0.0" />
    <axis xyz="0 1 0" />
    <limit lower="-1" upper="1" effort="1000.0" velocity="3.15"/>
    <dynamics damping="0.0" friction="0.0"/>
</joint>

<link name="${prefix}move_y_link">
</link>

<joint name="${prefix}rotate_theta_joint" type="revolute">
    <parent link="${prefix}move_y_link" />
    <child link = "${prefix}rotate_theta_link" />
    <origin xyz="0.0 0.0 0.0" rpy="0.0 0.0 0.0" />
    <axis xyz="0 0 1" />
    <limit lower="0" upper="0.5" effort="1000.0" velocity="3.15"/>
    <dynamics damping="0.0" friction="0.0"/>
</joint>

<link name="${prefix}rotate_theta_link" >
</link>

<joint name="${prefix}${arm_prefix}base_joint" type="fixed">
  <parent link="${prefix}move_z_link" />
  <child link = "${arm_prefix}base_link" />
  <origin xyz="0.0 0.0 0.61" rpy="0.0 0.0 0.0" />
</joint>

</xacro:macro>
</robot>